Workbook

Sheet Resultados
A1: XXIII Mundial USA/MEX/CAN 2026
B3: Fecha | C3: Hora | D3: Jor. | E3: Casa | F3: Gol | G3: Gol | H3: Fuera
A4: A | B4: 46184 | C4: 0.875 | D4: J1 | E4: México | F4: 2 | G4: 0 | H4: Sudáfrica
B5: 46185 | C5: 0.16666667 | D5: J1 | E5: Corea del Sur | F5: 2 | G5: 1 | H5: República Checa
B6: 46191 | C6: 0.75 | D6: J2 | E6: República Checa | H6: Sudáfrica
B7: 46192 | C7: 0.125 | D7: J2 | E7: México | H7: Corea del Sur
B8: 46198 | C8: 0.125 | D8: J3 | E8: República Checa | H8: México
B9: 46198 | C9: 0.125 | D9: J3 | E9: Sudáfrica | H9: Corea del Sur
B11: Fecha | C11: Hora | D11: Jor. | E11: Casa | F11: Gol | G11: Gol | H11: Fuera
A12: B | B12: 46185 | C12: 0.875 | D12: J1 | E12: Canadá | F12: 1 | G12: 1 | H12: Bosnia y Herzegovina
B13: 46186 | C13: 0.875 | D13: J1 | E13: Catar | F13: 1 | G13: 1 | H13: Suiza
B14: 46191 | C14: 0.875 | D14: J2 | E14: Suiza | H14: Bosnia y Herzegovina
B15: 46192 | C15: 0 | D15: J2 | E15: Canadá | H15: Catar
B16: 46197 | C16: 0.875 | D16: J3 | E16: Suiza | H16: Canadá
B17: 46197 | C17: 0.875 | D17: J3 | E17: Bosnia y Herzegovina | H17: Catar
B19: Fecha | C19: Hora | D19: Jor. | E19: Casa | F19: Gol | G19: Gol | H19: Fuera
A20: C | B20: 46187 | C20: 0 | D20: J1 | E20: Brasil | F20: 1 | G20: 1 | H20: Marruecos
B21: 46187 | C21: 0.125 | D21: J1 | E21: Haití | F21: 0 | G21: 1 | H21: Escocia
B22: 46193 | C22: 0 | D22: J2 | E22: Escocia | H22: Marruecos
B23: 46193 | C23: 0.10416667 | D23: J2 | E23: Brasil | H23: Haití
B24: 46198 | C24: 0 | D24: J3 | E24: Escocia | H24: Brasil
B25: 46198 | C25: 0 | D25: J3 | E25: Marruecos | H25: Haití
B27: Fecha | C27: Hora | D27: Jor. | E27: Casa | F27: Gol | G27: Gol | H27: Fuera
A28: D | B28: 46186 | C28: 0.125 | D28: J1 | E28: Estados Unidos | F28: 4 | G28: 1 | H28: Paraguay
B29: 46187 | C29: 0.25 | D29: J1 | E29: Australia | F29: 2 | G29: 0 | H29: Turquía
B30: 46192 | C30: 0.875 | D30: J2 | E30: Estados Unidos | H30: Australia
B31: 46193 | C31: 0.20833333 | D31: J2 | E31: Turquía | H31: Paraguay
B32: 46199 | C32: 0.16666667 | D32: J3 | E32: Turquía | H32: Estados Unidos
B33: 46199 | C33: 0.16666667 | D33: J3 | E33: Paraguay | H33: Australia
B35: Fecha | C35: Hora | D35: Jor. | E35: Casa | F35: Gol | G35: Gol | H35: Fuera
A36: E | B36: 46187 | C36: 0.79166667 | D36: J1 | E36: Alemania | F36: 7 | G36: 1 | H36: Curazao
B37: 46188 | C37: 0.041666667 | D37: J1 | E37: Costa de Marfil | F37: 1 | G37: 0 | H37: Ecuador
B38: 46193 | C38: 0.91666667 | D38: J2 | E38: Alemania | H38: Costa de Marfil
B39: 46194 | C39: 0.083333333 | D39: J2 | E39: Ecuador | H39: Curazao
B40: 46198 | C40: 0.91666667 | D40: J3 | E40: Curazao | H40: Costa de Marfil
B41: 46198 | C41: 0.91666667 | D41: J3 | E41: Ecuador | H41: Alemania
B43: Fecha | C43: Hora | D43: Jor. | E43: Casa | F43: Gol | G43: Gol | H43: Fuera
A44: F | B44: 46187 | C44: 0.91666667 | D44: J1 | E44: Países Bajos | F44: 2 | G44: 2 | H44: Japón
B45: 46188 | C45: 0.16666667 | D45: J1 | E45: Suecia | F45: 5 | G45: 1 | H45: Túnez
B46: 46193 | C46: 0.79166667 | D46: J2 | E46: Países Bajos | H46: Suecia
...

Sheet Ranking
D1: +2 puntos - marcador exacto
D2: +1 punto - resultado (ganador/empate)
A4: Usuario | B4: Puntos | D4: Posición | E4: Usuario | F4: Puntos
A5: Cindy | B5: =Cindy!L4 -> 3 | D5: 1 | E5: {=_xlfn._xlws.SORT(A5:B13,2,-1)} -> Lennon | F5: 6
A6: Wendy | B6: =Wendy!L4 -> 4 | D6: 2 | E6: Bere | F6: 5
A7: Jimmy | B7: =Jimmy!L4 -> 4 | D7: 3 | E7: Wendy | F7: 4
A8: Erick | B8: =Erick!L4 -> 4 | D8: 4 | E8: Jimmy | F8: 4
A9: Erik | B9: =Erik!L4 -> 4 | D9: 5 | E9: Erick | F9: 4
A10: Lennon | B10: =Lennon!L4 -> 6 | D10: 6 | E10: Erik | F10: 4
A11: Yulian | B11: =Yulian!L4 -> 3 | D11: 7 | E11: Cindy | F11: 3
A12: Packy | B12: =Packy!L4 -> 3 | D12: 8 | E12: Yulian | F12: 3
A13: Bere | B13: =Bere!L4 -> 5 | D13: 9 | E13: Packy | F13: 3

Sheet Cindy
A1: XXIII Mundial USA/MEX/CAN 2026
B3: Fecha | C3: Hora | D3: Jor. | E3: Local | F3: Gol | G3: Gol | H3: Visitante | J3: Puntos | L3: Total
A4: A | B4: 46184 | C4: 0.875 | D4: J1 | E4: México | F4: 2 | G4: 0 | H4: Sudáfrica | L4: =SUM(J:J) -> 3
B5: 46185 | C5: 0.16666667 | D5: J1 | E5: Corea del Sur | F5: 2 | G5: 1 | H5: República Checa
B6: 46191 | C6: 0.75 | D6: J2 | E6: República Checa | F6: 2 | G6: 0 | H6: Sudáfrica | J6: =IF(OR(Resultados!F6="",Resultados!G6=""),"",IF(AND(F6=Resultados!F6,G6=Resultados!G6),2,IF(((F6>G6)=(Resultados!F6>Resultados!G6))*((F6<G6)=(Resultados!F6<Resultados!G6)),1,0)))
B7: 46192 | C7: 0.125 | D7: J2 | E7: México | F7: 2 | G7: 1 | H7: Corea del Sur | J7: =IF(OR(Resultados!F7="",Resultados!G7=""),"",IF(AND(F7=Resultados!F7,G7=Resultados!G7),2,IF(((F7>G7)=(Resultados!F7>Resultados!G7))*((F7<G7)=(Resultados!F7<Resultados!G7)),1,0)))
B8: 46198 | C8: 0.125 | D8: J3 | E8: República Checa | F8: 1 | G8: 2 | H8: México | J8: =IF(OR(Resultados!F8="",Resultados!G8=""),"",IF(AND(F8=Resultados!F8,G8=Resultados!G8),2,IF(((F8>G8)=(Resultados!F8>Resultados!G8))*((F8<G8)=(Resultados!F8<Resultados!G8)),1,0)))
B9: 46198 | C9: 0.125 | D9: J3 | E9: Sudáfrica | F9: 1 | G9: 2 | H9: Corea del Sur | J9: =IF(OR(Resultados!F9="",Resultados!G9=""),"",IF(AND(F9=Resultados!F9,G9=Resultados!G9),2,IF(((F9>G9)=(Resultados!F9>Resultados!G9))*((F9<G9)=(Resultados!F9<Resultados!G9)),1,0)))
B11: Fecha | C11: Hora | D11: Jor. | E11: Local | F11: Gol | G11: Gol | H11: Visitante
A12: B | B12: 46185 | C12: 0.875 | D12: J1 | E12: Canadá | F12: 1 | G12: 1 | H12: Bosnia y Herzegovina
B13: 46186 | C13: 0.875 | D13: J1 | E13: Catar | F13: 1 | G13: 1 | H13: Suiza
B14: 46191 | C14: 0.875 | D14: J2 | E14: Suiza | F14: 2 | G14: 0 | H14: Bosnia y Herzegovina | J14: =IF(OR(Resultados!F14="",Resultados!G14=""),"",IF(AND(F14=Resultados!F14,G14=Resultados!G14),2,IF(((F14>G14)=(Resultados!F14>Resultados!G14))*((F14<G14)=(Resultados!F14<Resultados!G14)),1,0)))
B15: 46192 | C15: 0 | D15: J2 | E15: Canadá | F15: 2 | G15: 0 | H15: Catar | J15: =IF(OR(Resultados!F15="",Resultados!G15=""),"",IF(AND(F15=Resultados!F15,G15=Resultados!G15),2,IF(((F15>G15)=(Resultados!F15>Resultados!G15))*((F15<G15)=(Resultados!F15<Resultados!G15)),1,0)))
B16: 46197 | C16: 0.875 | D16: J3 | E16: Suiza | F16: 1 | G16: 0 | H16: Canadá | J16: =IF(OR(Resultados!F16="",Resultados!G16=""),"",IF(AND(F16=Resultados!F16,G16=Resultados!G16),2,IF(((F16>G16)=(Resultados!F16>Resultados!G16))*((F16<G16)=(Resultados!F16<Resultados!G16)),1,0)))
B17: 46197 | C17: 0.875 | D17: J3 | E17: Bosnia y Herzegovina | F17: 1 | G17: 0 | H17: Catar | J17: =IF(OR(Resultados!F17="",Resultados!G17=""),"",IF(AND(F17=Resultados!F17,G17=Resultados!G17),2,IF(((F17>G17)=(Resultados!F17>Resultados!G17))*((F17<G17)=(Resultados!F17<Resultados!G17)),1,0)))
B19: Fecha | C19: Hora | D19: Jor. | E19: Local | F19: Gol | G19: Gol | H19: Visitante
A20: C | B20: 46187 | C20: 0 | D20: J1 | E20: Brasil | F20: 1 | G20: 1 | H20: Marruecos
B21: 46187 | C21: 0.125 | D21: J1 | E21: Haití | F21: 0 | G21: 2 | H21: Escocia | J21: =IF(OR(Resultados!F21="",Resultados!G21=""),"",IF(AND(F21=Resultados!F21,G21=Resultados!G21),2,IF(((F21>G21)=(Resultados!F21>Resultados!G21))*((F21<G21)=(Resultados!F21<Resultados!G21)),1,0))) -> 1
B22: 46193 | C22: 0 | D22: J2 | E22: Escocia | F22: 0 | G22: 1 | H22: Marruecos | J22: =IF(OR(Resultados!F22="",Resultados!G22=""),"",IF(AND(F22=Resultados!F22,G22=Resultados!G22),2,IF(((F22>G22)=(Resultados!F22>Resultados!G22))*((F22<G22)=(Resultados!F22<Resultados!G22)),1,0)))
B23: 46193 | C23: 0.10416667 | D23: J2 | E23: Brasil | F23: 3 | G23: 0 | H23: Haití | J23: =IF(OR(Resultados!F23="",Resultados!G23=""),"",IF(AND(F23=Resultados!F23,G23=Resultados!G23),2,IF(((F23>G23)=(Resultados!F23>Resultados!G23))*((F23<G23)=(Resultados!F23<Resultados!G23)),1,0)))
B24: 46198 | C24: 0 | D24: J3 | E24: Escocia | F24: 0 | G24: 2 | H24: Brasil | J24: =IF(OR(Resultados!F24="",Resultados!G24=""),"",IF(AND(F24=Resultados!F24,G24=Resultados!G24),2,IF(((F24>G24)=(Resultados!F24>Resultados!G24))*((F24<G24)=(Resultados!F24<Resultados!G24)),1,0)))
B25: 46198 | C25: 0 | D25: J3 | E25: Marruecos | F25: 2 | G25: 0 | H25: Haití | J25: =IF(OR(Resultados!F25="",Resultados!G25=""),"",IF(AND(F25=Resultados!F25,G25=Resultados!G25),2,IF(((F25>G25)=(Resultados!F25>Resultados!G25))*((F25<G25)=(Resultados!F25<Resultados!G25)),1,0)))
B27: Fecha | C27: Hora | D27: Jor. | E27: Local | F27: Gol | G27: Gol | H27: Visitante
A28: D | B28: 46186 | C28: 0.125 | D28: J1 | E28: Estados Unidos | F28: 4 | G28: 1 | H28: Paraguay
B29: 46187 | C29: 0.25 | D29: J1 | E29: Australia | F29: 0 | G29: 1 | H29: Turquía | J29: =IF(OR(Resultados!F29="",Resultados!G29=""),"",IF(AND(F29=Resultados!F29,G29=Resultados!G29),2,IF(((F29>G29)=(Resultados!F29>Resultados!G29))*((F29<G29)=(Resultados!F29<Resultados!G29)),1,0))) -> 0
B30: 46192 | C30: 0.875 | D30: J2 | E30: Estados Unidos | F30: 1 | G30: 0 | H30: Australia | J30: =IF(OR(Resultados!F30="",Resultados!G30=""),"",IF(AND(F30=Resultados!F30,G30=Resultados!G30),2,IF(((F30>G30)=(Resultados!F30>Resultados!G30))*((F30<G30)=(Resultados!F30<Resultados!G30)),1,0)))
B31: 46193 | C31: 0.20833333 | D31: J2 | E31: Turquía | F31: 2 | G31: 1 | H31: Paraguay | J31: =IF(OR(Resultados!F31="",Resultados!G31=""),"",IF(AND(F31=Resultados!F31,G31=Resultados!G31),2,IF(((F31>G31)=(Resultados!F31>Resultados!G31))*((F31<G31)=(Resultados!F31<Resultados!G31)),1,0)))
B32: 46199 | C32: 0.16666667 | D32: J3 | E32: Turquía | F32: 1 | G32: 1 | H32: Estados Unidos | J32: =IF(OR(Resultados!F32="",Resultados!G32=""),"",IF(AND(F32=Resultados!F32,G32=Resultados!G32),2,IF(((F32>G32)=(Resultados!F32>Resultados!G32))*((F32<G32)=(Resultados!F32<Resultados!G32)),1,0)))
B33: 46199 | C33: 0.16666667 | D33: J3 | E33: Paraguay | F33: 1 | G33: 0 | H33: Australia | J33: =IF(OR(Resultados!F33="",Resultados!G33=""),"",IF(AND(F33=Resultados!F33,G33=Resultados!G33),2,IF(((F33>G33)=(Resultados!F33>Resultados!G33))*((F33<G33)=(Resultados!F33<Resultados!G33)),1,0)))
B35: Fecha | C35: Hora | D35: Jor. | E35: Local | F35: Gol | G35: Gol | H35: Visitante
A36: E | B36: 46187 | C36: 0.79166667 | D36: J1 | E36: Alemania | F36: 3 | G36: 0 | H36: Curazao | J36: =IF(OR(Resultados!F36="",Resultados!G36=""),"",IF(AND(F36=Resultados!F36,G36=Resultados!G36),2,IF(((F36>G36)=(Resultados!F36>Resultados!G36))*((F36<G36)=(Resultados!F36<Resultados!G36)),1,0))) -> 1
B37: 46188 | C37: 0.041666667 | D37: J1 | E37: Costa de Marfil | F37: 1 | G37: 1 | H37: Ecuador | J37: =IF(OR(Resultados!F37="",Resultados!G37=""),"",IF(AND(F37=Resultados!F37,G37=Resultados!G37),2,IF(((F37>G37)=(Resultados!F37>Resultados!G37))*((F37<G37)=(Resultados!F37<Resultados!G37)),1,0))) -> 0
B38: 46193 | C38: 0.91666667 | D38: J2 | E38: Alemania | F38: 2 | G38: 0 | H38: Costa de Marfil | J38: =IF(OR(Resultados!F38="",Resultados!G38=""),"",IF(AND(F38=Resultados!F38,G38=Resultados!G38),2,IF(((F38>G38)=(Resultados!F38>Resultados!G38))*((F38<G38)=(Resultados!F38<Resultados!G38)),1,0)))
B39: 46194 | C39: 0.083333333 | D39: J2 | E39: Ecuador | F39: 2 | G39: 0 | H39: Curazao | J39: =IF(OR(Resultados!F39="",Resultados!G39=""),"",IF(AND(F39=Resultados!F39,G39=Resultados!G39),2,IF(((F39>G39)=(Resultados!F39>Resultados!G39))*((F39<G39)=(Resultados!F39<Resultados!G39)),1,0)))
B40: 46198 | C40: 0.91666667 | D40: J3 | E40: Curazao | F40: 0 | G40: 2 | H40: Costa de Marfil | J40: =IF(OR(Resultados!F40="",Resultados!G40=""),"",IF(AND(F40=Resultados!F40,G40=Resultados!G40),2,IF(((F40>G40)=(Resultados!F40>Resultados!G40))*((F40<G40)=(Resultados!F40<Resultados!G40)),1,0)))
B41: 46198 | C41: 0.91666667 | D41: J3 | E41: Ecuador | F41: 0 | G41: 2 | H41: Alemania | J41: =IF(OR(Resultados!F41="",Resultados!G41=""),"",IF(AND(F41=Resultados!F41,G41=Resultados!G41),2,IF(((F41>G41)=(Resultados!F41>Resultados!G41))*((F41<G41)=(Resultados!F41<Resultados!G41)),1,0)))
B43: Fecha | C43: Hora | D43: Jor. | E43: Local | F43: Gol | G43: Gol | H43: Visitante
A44: F | B44: 46187 | C44: 0.91666667 | D44: J1 | E44: Países Bajos | F44: 2 | G44: 1 | H44: Japón | J44: =IF(OR(Resultados!F44="",Resultados!G44=""),"",IF(AND(F44=Resultados!F44,G44=Resultados!G44),2,IF(((F44>G44)=(Resultados!F44>Resultados!G44))*((F44<G44)=(Resultados!F44<Resultados!G44)),1,0))) -> 0
B45: 46188 | C45: 0.16666667 | D45: J1 | E45: Suecia | F45: 1 | G45: 0 | H45: Túnez | J45: =IF(OR(Resultados!F45="",Resultados!G45=""),"",IF(AND(F45=Resultados!F45,G45=Resultados!G45),2,IF(((F45>G45)=(Resultados!F45>Resultados!G45))*((F45<G45)=(Resultados!F45<Resultados!G45)),1,0))) -> 1
B46: 46193 | C46: 0.79166667 | D46: J2 | E46: Países Bajos | F46: 2 | G46: 1 | H46: Suecia | J46: =IF(OR(Resultados!F46="",Resultados!G46=""),"",IF(AND(F46=Resultados!F46,G46=Resultados!G46),2,IF(((F46>G46)=(Resultados!F46>Resultados!G46))*((F46<G46)=(Resultados!F46<Resultados!G46)),1,0)))
...

Sheet Wendy
A1: XXIII Mundial USA/MEX/CAN 2026
B3: Fecha | C3: Hora | D3: Jor. | E3: Casa | F3: Gol | G3: Gol | H3: Fuera | J3: Puntos | L3: Total
A4: A | B4: 46184 | C4: 0.875 | D4: J1 | E4: México | F4: 2 | G4: 0 | H4: Sudáfrica | L4: =SUM(J:J) -> 4
B5: 46185 | C5: 0.16666667 | D5: J1 | E5: Corea del Sur | F5: 2 | G5: 1 | H5: República Checa
B6: 46191 | C6: 0.75 | D6: J2 | E6: República Checa | F6: 2 | G6: 0 | H6: Sudáfrica | J6: =IF(OR(Resultados!F6="",Resultados!G6=""),"",IF(AND(F6=Resultados!F6,G6=Resultados!G6),2,IF(((F6>G6)=(Resultados!F6>Resultados!G6))*((F6<G6)=(Resultados!F6<Resultados!G6)),1,0)))
B7: 46192 | C7: 0.125 | D7: J2 | E7: México | F7: 3 | G7: 1 | H7: Corea del Sur | J7: =IF(OR(Resultados!F7="",Resultados!G7=""),"",IF(AND(F7=Resultados!F7,G7=Resultados!G7),2,IF(((F7>G7)=(Resultados!F7>Resultados!G7))*((F7<G7)=(Resultados!F7<Resultados!G7)),1,0)))
B8: 46198 | C8: 0.125 | D8: J3 | E8: República Checa | F8: 1 | G8: 2 | H8: México | J8: =IF(OR(Resultados!F8="",Resultados!G8=""),"",IF(AND(F8=Resultados!F8,G8=Resultados!G8),2,IF(((F8>G8)=(Resultados!F8>Resultados!G8))*((F8<G8)=(Resultados!F8<Resultados!G8)),1,0)))
B9: 46198 | C9: 0.125 | D9: J3 | E9: Sudáfrica | F9: 1 | G9: 1 | H9: Corea del Sur | J9: =IF(OR(Resultados!F9="",Resultados!G9=""),"",IF(AND(F9=Resultados!F9,G9=Resultados!G9),2,IF(((F9>G9)=(Resultados!F9>Resultados!G9))*((F9<G9)=(Resultados!F9<Resultados!G9)),1,0)))
B11: Fecha | C11: Hora | D11: Jor. | E11: Casa | F11: Gol | G11: Gol | H11: Fuera
A12: B | B12: 46185 | C12: 0.875 | D12: J1 | E12: Canadá | F12: 1 | G12: 1 | H12: Bosnia y Herzegovina
B13: 46186 | C13: 0.875 | D13: J1 | E13: Catar | F13: 1 | G13: 1 | H13: Suiza
B14: 46191 | C14: 0.875 | D14: J2 | E14: Suiza | F14: 1 | G14: 0 | H14: Bosnia y Herzegovina | J14: =IF(OR(Resultados!F14="",Resultados!G14=""),"",IF(AND(F14=Resultados!F14,G14=Resultados!G14),2,IF(((F14>G14)=(Resultados!F14>Resultados!G14))*((F14<G14)=(Resultados!F14<Resultados!G14)),1,0)))
B15: 46192 | C15: 0 | D15: J2 | E15: Canadá | F15: 2 | G15: 1 | H15: Catar | J15: =IF(OR(Resultados!F15="",Resultados!G15=""),"",IF(AND(F15=Resultados!F15,G15=Resultados!G15),2,IF(((F15>G15)=(Resultados!F15>Resultados!G15))*((F15<G15)=(Resultados!F15<Resultados!G15)),1,0)))
B16: 46197 | C16: 0.875 | D16: J3 | E16: Suiza | F16: 0 | G16: 2 | H16: Canadá | J16: =IF(OR(Resultados!F16="",Resultados!G16=""),"",IF(AND(F16=Resultados!F16,G16=Resultados!G16),2,IF(((F16>G16)=(Resultados!F16>Resultados!G16))*((F16<G16)=(Resultados!F16<Resultados!G16)),1,0)))
B17: 46197 | C17: 0.875 | D17: J3 | E17: Bosnia y Herzegovina | F17: 0 | G17: 1 | H17: Catar | J17: =IF(OR(Resultados!F17="",Resultados!G17=""),"",IF(AND(F17=Resultados!F17,G17=Resultados!G17),2,IF(((F17>G17)=(Resultados!F17>Resultados!G17))*((F17<G17)=(Resultados!F17<Resultados!G17)),1,0)))
B19: Fecha | C19: Hora | D19: Jor. | E19: Casa | F19: Gol | G19: Gol | H19: Fuera
A20: C | B20: 46187 | C20: 0 | D20: J1 | E20: Brasil | F20: 1 | G20: 1 | H20: Marruecos
B21: 46187 | C21: 0.125 | D21: J1 | E21: Haití | F21: 0 | G21: 2 | H21: Escocia | J21: =IF(OR(Resultados!F21="",Resultados!G21=""),"",IF(AND(F21=Resultados!F21,G21=Resultados!G21),2,IF(((F21>G21)=(Resultados!F21>Resultados!G21))*((F21<G21)=(Resultados!F21<Resultados!G21)),1,0))) -> 1
B22: 46193 | C22: 0 | D22: J2 | E22: Escocia | F22: 1 | G22: 1 | H22: Marruecos | J22: =IF(OR(Resultados!F22="",Resultados!G22=""),"",IF(AND(F22=Resultados!F22,G22=Resultados!G22),2,IF(((F22>G22)=(Resultados!F22>Resultados!G22))*((F22<G22)=(Resultados!F22<Resultados!G22)),1,0)))
B23: 46193 | C23: 0.10416667 | D23: J2 | E23: Brasil | F23: 4 | G23: 0 | H23: Haití | J23: =IF(OR(Resultados!F23="",Resultados!G23=""),"",IF(AND(F23=Resultados!F23,G23=Resultados!G23),2,IF(((F23>G23)=(Resultados!F23>Resultados!G23))*((F23<G23)=(Resultados!F23<Resultados!G23)),1,0)))
B24: 46198 | C24: 0 | D24: J3 | E24: Escocia | F24: 1 | G24: 3 | H24: Brasil | J24: =IF(OR(Resultados!F24="",Resultados!G24=""),"",IF(AND(F24=Resultados!F24,G24=Resultados!G24),2,IF(((F24>G24)=(Resultados!F24>Resultados!G24))*((F24<G24)=(Resultados!F24<Resultados!G24)),1,0)))
B25: 46198 | C25: 0 | D25: J3 | E25: Marruecos | F25: 2 | G25: 2 | H25: Haití | J25: =IF(OR(Resultados!F25="",Resultados!G25=""),"",IF(AND(F25=Resultados!F25,G25=Resultados!G25),2,IF(((F25>G25)=(Resultados!F25>Resultados!G25))*((F25<G25)=(Resultados!F25<Resultados!G25)),1,0)))
B27: Fecha | C27: Hora | D27: Jor. | E27: Casa | F27: Gol | G27: Gol | H27: Fuera
A28: D | B28: 46186 | C28: 0.125 | D28: J1 | E28: Estados Unidos | F28: 4 | G28: 1 | H28: Paraguay
B29: 46187 | C29: 0.25 | D29: J1 | E29: Australia | F29: 1 | G29: 0 | H29: Turquía | J29: =IF(OR(Resultados!F29="",Resultados!G29=""),"",IF(AND(F29=Resultados!F29,G29=Resultados!G29),2,IF(((F29>G29)=(Resultados!F29>Resultados!G29))*((F29<G29)=(Resultados!F29<Resultados!G29)),1,0))) -> 1
B30: 46192 | C30: 0.875 | D30: J2 | E30: Estados Unidos | F30: 3 | G30: 1 | H30: Australia | J30: =IF(OR(Resultados!F30="",Resultados!G30=""),"",IF(AND(F30=Resultados!F30,G30=Resultados!G30),2,IF(((F30>G30)=(Resultados!F30>Resultados!G30))*((F30<G30)=(Resultados!F30<Resultados!G30)),1,0)))
B31: 46193 | C31: 0.20833333 | D31: J2 | E31: Turquía | F31: 0 | G31: 1 | H31: Paraguay | J31: =IF(OR(Resultados!F31="",Resultados!G31=""),"",IF(AND(F31=Resultados!F31,G31=Resultados!G31),2,IF(((F31>G31)=(Resultados!F31>Resultados!G31))*((F31<G31)=(Resultados!F31<Resultados!G31)),1,0)))
B32: 46199 | C32: 0.16666667 | D32: J3 | E32: Turquía | F32: 0 | G32: 1 | H32: Estados Unidos | J32: =IF(OR(Resultados!F32="",Resultados!G32=""),"",IF(AND(F32=Resultados!F32,G32=Resultados!G32),2,IF(((F32>G32)=(Resultados!F32>Resultados!G32))*((F32<G32)=(Resultados!F32<Resultados!G32)),1,0)))
B33: 46199 | C33: 0.16666667 | D33: J3 | E33: Paraguay | F33: 2 | G33: 1 | H33: Australia | J33: =IF(OR(Resultados!F33="",Resultados!G33=""),"",IF(AND(F33=Resultados!F33,G33=Resultados!G33),2,IF(((F33>G33)=(Resultados!F33>Resultados!G33))*((F33<G33)=(Resultados!F33<Resultados!G33)),1,0)))
B35: Fecha | C35: Hora | D35: Jor. | E35: Casa | F35: Gol | G35: Gol | H35: Fuera
A36: E | B36: 46187 | C36: 0.79166667 | D36: J1 | E36: Alemania | F36: 3 | G36: 0 | H36: Curazao | J36: =IF(OR(Resultados!F36="",Resultados!G36=""),"",IF(AND(F36=Resultados!F36,G36=Resultados!G36),2,IF(((F36>G36)=(Resultados!F36>Resultados!G36))*((F36<G36)=(Resultados!F36<Resultados!G36)),1,0))) -> 1
B37: 46188 | C37: 0.041666667 | D37: J1 | E37: Costa de Marfil | F37: 0 | G37: 1 | H37: Ecuador | J37: =IF(OR(Resultados!F37="",Resultados!G37=""),"",IF(AND(F37=Resultados!F37,G37=Resultados!G37),2,IF(((F37>G37)=(Resultados!F37>Resultados!G37))*((F37<G37)=(Resultados!F37<Resultados!G37)),1,0))) -> 0
B38: 46193 | C38: 0.91666667 | D38: J2 | E38: Alemania | F38: 4 | G38: 1 | H38: Costa de Marfil | J38: =IF(OR(Resultados!F38="",Resultados!G38=""),"",IF(AND(F38=Resultados!F38,G38=Resultados!G38),2,IF(((F38>G38)=(Resultados!F38>Resultados!G38))*((F38<G38)=(Resultados!F38<Resultados!G38)),1,0)))
B39: 46194 | C39: 0.083333333 | D39: J2 | E39: Ecuador | F39: 3 | G39: 1 | H39: Curazao | J39: =IF(OR(Resultados!F39="",Resultados!G39=""),"",IF(AND(F39=Resultados!F39,G39=Resultados!G39),2,IF(((F39>G39)=(Resultados!F39>Resultados!G39))*((F39<G39)=(Resultados!F39<Resultados!G39)),1,0)))
B40: 46198 | C40: 0.91666667 | D40: J3 | E40: Curazao | F40: 1 | G40: 1 | H40: Costa de Marfil | J40: =IF(OR(Resultados!F40="",Resultados!G40=""),"",IF(AND(F40=Resultados!F40,G40=Resultados!G40),2,IF(((F40>G40)=(Resultados!F40>Resultados!G40))*((F40<G40)=(Resultados!F40<Resultados!G40)),1,0)))
B41: 46198 | C41: 0.91666667 | D41: J3 | E41: Ecuador | F41: 1 | G41: 3 | H41: Alemania | J41: =IF(OR(Resultados!F41="",Resultados!G41=""),"",IF(AND(F41=Resultados!F41,G41=Resultados!G41),2,IF(((F41>G41)=(Resultados!F41>Resultados!G41))*((F41<G41)=(Resultados!F41<Resultados!G41)),1,0)))
B43: Fecha | C43: Hora | D43: Jor. | E43: Casa | F43: Gol | G43: Gol | H43: Fuera
A44: F | B44: 46187 | C44: 0.91666667 | D44: J1 | E44: Países Bajos | F44: 1 | G44: 2 | H44: Japón | J44: =IF(OR(Resultados!F44="",Resultados!G44=""),"",IF(AND(F44=Resultados!F44,G44=Resultados!G44),2,IF(((F44>G44)=(Resultados!F44>Resultados!G44))*((F44<G44)=(Resultados!F44<Resultados!G44)),1,0))) -> 0
B45: 46188 | C45: 0.16666667 | D45: J1 | E45: Suecia | F45: 1 | G45: 0 | H45: Túnez | J45: =IF(OR(Resultados!F45="",Resultados!G45=""),"",IF(AND(F45=Resultados!F45,G45=Resultados!G45),2,IF(((F45>G45)=(Resultados!F45>Resultados!G45))*((F45<G45)=(Resultados!F45<Resultados!G45)),1,0))) -> 1
B46: 46193 | C46: 0.79166667 | D46: J2 | E46: Países Bajos | F46: 0 | G46: 1 | H46: Suecia | J46: =IF(OR(Resultados!F46="",Resultados!G46=""),"",IF(AND(F46=Resultados!F46,G46=Resultados!G46),2,IF(((F46>G46)=(Resultados!F46>Resultados!G46))*((F46<G46)=(Resultados!F46<Resultados!G46)),1,0)))
...

Sheet Packy
A1: XXIII Mundial USA/MEX/CAN 2026
B3: Fecha | C3: Hora | D3: Jor. | E3: Casa | F3: Gol | G3: Gol | H3: Fuera | J3: Puntos | L3: Total
A4: A | B4: 46184 | C4: 0.875 | D4: J1 | E4: México | F4: 2 | G4: 0 | H4: Sudáfrica | L4: =SUM(J:J) -> 3
B5: 46185 | C5: 0.16666667 | D5: J1 | E5: Corea del Sur | F5: 2 | G5: 1 | H5: República Checa
B6: 46191 | C6: 0.75 | D6: J2 | E6: República Checa | F6: 2 | G6: 0 | H6: Sudáfrica | J6: =IF(OR(Resultados!F6="",Resultados!G6=""),"",IF(AND(F6=Resultados!F6,G6=Resultados!G6),2,IF(((F6>G6)=(Resultados!F6>Resultados!G6))*((F6<G6)=(Resultados!F6<Resultados!G6)),1,0)))
B7: 46192 | C7: 0.125 | D7: J2 | E7: México | F7: 1 | G7: 1 | H7: Corea del Sur | J7: =IF(OR(Resultados!F7="",Resultados!G7=""),"",IF(AND(F7=Resultados!F7,G7=Resultados!G7),2,IF(((F7>G7)=(Resultados!F7>Resultados!G7))*((F7<G7)=(Resultados!F7<Resultados!G7)),1,0)))
B8: 46198 | C8: 0.125 | D8: J3 | E8: República Checa | F8: 0 | G8: 1 | H8: México | J8: =IF(OR(Resultados!F8="",Resultados!G8=""),"",IF(AND(F8=Resultados!F8,G8=Resultados!G8),2,IF(((F8>G8)=(Resultados!F8>Resultados!G8))*((F8<G8)=(Resultados!F8<Resultados!G8)),1,0)))
B9: 46198 | C9: 0.125 | D9: J3 | E9: Sudáfrica | F9: 0 | G9: 3 | H9: Corea del Sur | J9: =IF(OR(Resultados!F9="",Resultados!G9=""),"",IF(AND(F9=Resultados!F9,G9=Resultados!G9),2,IF(((F9>G9)=(Resultados!F9>Resultados!G9))*((F9<G9)=(Resultados!F9<Resultados!G9)),1,0)))
B11: Fecha | C11: Hora | D11: Jor. | E11: Casa | F11: Gol | G11: Gol | H11: Fuera
A12: B | B12: 46185 | C12: 0.875 | D12: J1 | E12: Canadá | F12: 1 | G12: 1 | H12: Bosnia y Herzegovina
B13: 46186 | C13: 0.875 | D13: J1 | E13: Catar | F13: 1 | G13: 1 | H13: Suiza
B14: 46191 | C14: 0.875 | D14: J2 | E14: Suiza | F14: 2 | G14: 1 | H14: Bosnia y Herzegovina | J14: =IF(OR(Resultados!F14="",Resultados!G14=""),"",IF(AND(F14=Resultados!F14,G14=Resultados!G14),2,IF(((F14>G14)=(Resultados!F14>Resultados!G14))*((F14<G14)=(Resultados!F14<Resultados!G14)),1,0)))
B15: 46192 | C15: 0 | D15: J2 | E15: Canadá | F15: 1 | G15: 0 | H15: Catar | J15: =IF(OR(Resultados!F15="",Resultados!G15=""),"",IF(AND(F15=Resultados!F15,G15=Resultados!G15),2,IF(((F15>G15)=(Resultados!F15>Resultados!G15))*((F15<G15)=(Resultados!F15<Resultados!G15)),1,0)))
B16: 46197 | C16: 0.875 | D16: J3 | E16: Suiza | F16: 0 | G16: 1 | H16: Canadá | J16: =IF(OR(Resultados!F16="",Resultados!G16=""),"",IF(AND(F16=Resultados!F16,G16=Resultados!G16),2,IF(((F16>G16)=(Resultados!F16>Resultados!G16))*((F16<G16)=(Resultados!F16<Resultados!G16)),1,0)))
B17: 46197 | C17: 0.875 | D17: J3 | E17: Bosnia y Herzegovina | F17: 1 | G17: 1 | H17: Catar | J17: =IF(OR(Resultados!F17="",Resultados!G17=""),"",IF(AND(F17=Resultados!F17,G17=Resultados!G17),2,IF(((F17>G17)=(Resultados!F17>Resultados!G17))*((F17<G17)=(Resultados!F17<Resultados!G17)),1,0)))
B19: Fecha | C19: Hora | D19: Jor. | E19: Casa | F19: Gol | G19: Gol | H19: Fuera
A20: C | B20: 46187 | C20: 0 | D20: J1 | E20: Brasil | F20: 1 | G20: 1 | H20: Marruecos
B21: 46187 | C21: 0.125 | D21: J1 | E21: Haití | F21: 0 | G21: 2 | H21: Escocia | J21: =IF(OR(Resultados!F21="",Resultados!G21=""),"",IF(AND(F21=Resultados!F21,G21=Resultados!G21),2,IF(((F21>G21)=(Resultados!F21>Resultados!G21))*((F21<G21)=(Resultados!F21<Resultados!G21)),1,0))) -> 1
B22: 46193 | C22: 0 | D22: J2 | E22: Escocia | F22: 0 | G22: 2 | H22: Marruecos | J22: =IF(OR(Resultados!F22="",Resultados!G22=""),"",IF(AND(F22=Resultados!F22,G22=Resultados!G22),2,IF(((F22>G22)=(Resultados!F22>Resultados!G22))*((F22<G22)=(Resultados!F22<Resultados!G22)),1,0)))
B23: 46193 | C23: 0.10416667 | D23: J2 | E23: Brasil | F23: 4 | G23: 0 | H23: Haití | J23: =IF(OR(Resultados!F23="",Resultados!G23=""),"",IF(AND(F23=Resultados!F23,G23=Resultados!G23),2,IF(((F23>G23)=(Resultados!F23>Resultados!G23))*((F23<G23)=(Resultados!F23<Resultados!G23)),1,0)))
B24: 46198 | C24: 0 | D24: J3 | E24: Escocia | F24: 0 | G24: 2 | H24: Brasil | J24: =IF(OR(Resultados!F24="",Resultados!G24=""),"",IF(AND(F24=Resultados!F24,G24=Resultados!G24),2,IF(((F24>G24)=(Resultados!F24>Resultados!G24))*((F24<G24)=(Resultados!F24<Resultados!G24)),1,0)))
B25: 46198 | C25: 0 | D25: J3 | E25: Marruecos | F25: 4 | G25: 0 | H25: Haití | J25: =IF(OR(Resultados!F25="",Resultados!G25=""),"",IF(AND(F25=Resultados!F25,G25=Resultados!G25),2,IF(((F25>G25)=(Resultados!F25>Resultados!G25))*((F25<G25)=(Resultados!F25<Resultados!G25)),1,0)))
B27: Fecha | C27: Hora | D27: Jor. | E27: Casa | F27: Gol | G27: Gol | H27: Fuera
A28: D | B28: 46186 | C28: 0.125 | D28: J1 | E28: Estados Unidos | F28: 4 | G28: 1 | H28: Paraguay
B29: 46187 | C29: 0.25 | D29: J1 | E29: Australia | F29: 0 | G29: 2 | H29: Turquía | J29: =IF(OR(Resultados!F29="",Resultados!G29=""),"",IF(AND(F29=Resultados!F29,G29=Resultados!G29),2,IF(((F29>G29)=(Resultados!F29>Resultados!G29))*((F29<G29)=(Resultados!F29<Resultados!G29)),1,0))) -> 0
B30: 46192 | C30: 0.875 | D30: J2 | E30: Estados Unidos | F30: 2 | G30: 0 | H30: Australia | J30: =IF(OR(Resultados!F30="",Resultados!G30=""),"",IF(AND(F30=Resultados!F30,G30=Resultados!G30),2,IF(((F30>G30)=(Resultados!F30>Resultados!G30))*((F30<G30)=(Resultados!F30<Resultados!G30)),1,0)))
B31: 46193 | C31: 0.20833333 | D31: J2 | E31: Turquía | F31: 2 | G31: 0 | H31: Paraguay | J31: =IF(OR(Resultados!F31="",Resultados!G31=""),"",IF(AND(F31=Resultados!F31,G31=Resultados!G31),2,IF(((F31>G31)=(Resultados!F31>Resultados!G31))*((F31<G31)=(Resultados!F31<Resultados!G31)),1,0)))
B32: 46199 | C32: 0.16666667 | D32: J3 | E32: Turquía | F32: 1 | G32: 2 | H32: Estados Unidos | J32: =IF(OR(Resultados!F32="",Resultados!G32=""),"",IF(AND(F32=Resultados!F32,G32=Resultados!G32),2,IF(((F32>G32)=(Resultados!F32>Resultados!G32))*((F32<G32)=(Resultados!F32<Resultados!G32)),1,0)))
B33: 46199 | C33: 0.16666667 | D33: J3 | E33: Paraguay | F33: 1 | G33: 1 | H33: Australia | J33: =IF(OR(Resultados!F33="",Resultados!G33=""),"",IF(AND(F33=Resultados!F33,G33=Resultados!G33),2,IF(((F33>G33)=(Resultados!F33>Resultados!G33))*((F33<G33)=(Resultados!F33<Resultados!G33)),1,0)))
B35: Fecha | C35: Hora | D35: Jor. | E35: Casa | F35: Gol | G35: Gol | H35: Fuera
A36: E | B36: 46187 | C36: 0.79166667 | D36: J1 | E36: Alemania | F36: 4 | G36: 0 | H36: Curazao | J36: =IF(OR(Resultados!F36="",Resultados!G36=""),"",IF(AND(F36=Resultados!F36,G36=Resultados!G36),2,IF(((F36>G36)=(Resultados!F36>Resultados!G36))*((F36<G36)=(Resultados!F36<Resultados!G36)),1,0))) -> 1
B37: 46188 | C37: 0.041666667 | D37: J1 | E37: Costa de Marfil | F37: 0 | G37: 2 | H37: Ecuador | J37: =IF(OR(Resultados!F37="",Resultados!G37=""),"",IF(AND(F37=Resultados!F37,G37=Resultados!G37),2,IF(((F37>G37)=(Resultados!F37>Resultados!G37))*((F37<G37)=(Resultados!F37<Resultados!G37)),1,0))) -> 0
B38: 46193 | C38: 0.91666667 | D38: J2 | E38: Alemania | F38: 3 | G38: 1 | H38: Costa de Marfil | J38: =IF(OR(Resultados!F38="",Resultados!G38=""),"",IF(AND(F38=Resultados!F38,G38=Resultados!G38),2,IF(((F38>G38)=(Resultados!F38>Resultados!G38))*((F38<G38)=(Resultados!F38<Resultados!G38)),1,0)))
B39: 46194 | C39: 0.083333333 | D39: J2 | E39: Ecuador | F39: 2 | G39: 0 | H39: Curazao | J39: =IF(OR(Resultados!F39="",Resultados!G39=""),"",IF(AND(F39=Resultados!F39,G39=Resultados!G39),2,IF(((F39>G39)=(Resultados!F39>Resultados!G39))*((F39<G39)=(Resultados!F39<Resultados!G39)),1,0)))
B40: 46198 | C40: 0.91666667 | D40: J3 | E40: Curazao | F40: 0 | G40: 3 | H40: Costa de Marfil | J40: =IF(OR(Resultados!F40="",Resultados!G40=""),"",IF(AND(F40=Resultados!F40,G40=Resultados!G40),2,IF(((F40>G40)=(Resultados!F40>Resultados!G40))*((F40<G40)=(Resultados!F40<Resultados!G40)),1,0)))
B41: 46198 | C41: 0.91666667 | D41: J3 | E41: Ecuador | F41: 1 | G41: 1 | H41: Alemania | J41: =IF(OR(Resultados!F41="",Resultados!G41=""),"",IF(AND(F41=Resultados!F41,G41=Resultados!G41),2,IF(((F41>G41)=(Resultados!F41>Resultados!G41))*((F41<G41)=(Resultados!F41<Resultados!G41)),1,0)))
B43: Fecha | C43: Hora | D43: Jor. | E43: Casa | F43: Gol | G43: Gol | H43: Fuera
A44: F | B44: 46187 | C44: 0.91666667 | D44: J1 | E44: Países Bajos | F44: 0 | G44: 2 | H44: Japón | J44: =IF(OR(Resultados!F44="",Resultados!G44=""),"",IF(AND(F44=Resultados!F44,G44=Resultados!G44),2,IF(((F44>G44)=(Resultados!F44>Resultados!G44))*((F44<G44)=(Resultados!F44<Resultados!G44)),1,0))) -> 0
B45: 46188 | C45: 0.16666667 | D45: J1 | E45: Suecia | F45: 2 | G45: 0 | H45: Túnez | J45: =IF(OR(Resultados!F45="",Resultados!G45=""),"",IF(AND(F45=Resultados!F45,G45=Resultados!G45),2,IF(((F45>G45)=(Resultados!F45>Resultados!G45))*((F45<G45)=(Resultados!F45<Resultados!G45)),1,0))) -> 1
B46: 46193 | C46: 0.79166667 | D46: J2 | E46: Países Bajos | F46: 2 | G46: 2 | H46: Suecia | J46: =IF(OR(Resultados!F46="",Resultados!G46=""),"",IF(AND(F46=Resultados!F46,G46=Resultados!G46),2,IF(((F46>G46)=(Resultados!F46>Resultados!G46))*((F46<G46)=(Resultados!F46<Resultados!G46)),1,0)))
...

Sheet Jimmy
A1: XXIII Mundial USA/MEX/CAN 2026
B3: Fecha | C3: Hora | D3: Jor. | E3: Casa | F3: Gol | G3: Gol | H3: Fuera | J3: Puntos | L3: Total
A4: A | B4: 46184 | C4: 0.875 | D4: J1 | E4: México | F4: 2 | G4: 0 | H4: Sudáfrica | L4: =SUM(J:J) -> 4
B5: 46185 | C5: 0.16666667 | D5: J1 | E5: Corea del Sur | F5: 2 | G5: 1 | H5: República Checa
B6: 46191 | C6: 0.75 | D6: J2 | E6: República Checa | F6: 3 | G6: 0 | H6: Sudáfrica | J6: =IF(OR(Resultados!F6="",Resultados!G6=""),"",IF(AND(F6=Resultados!F6,G6=Resultados!G6),2,IF(((F6>G6)=(Resultados!F6>Resultados!G6))*((F6<G6)=(Resultados!F6<Resultados!G6)),1,0)))
B7: 46192 | C7: 0.125 | D7: J2 | E7: México | F7: 1 | G7: 1 | H7: Corea del Sur | J7: =IF(OR(Resultados!F7="",Resultados!G7=""),"",IF(AND(F7=Resultados!F7,G7=Resultados!G7),2,IF(((F7>G7)=(Resultados!F7>Resultados!G7))*((F7<G7)=(Resultados!F7<Resultados!G7)),1,0)))
B8: 46198 | C8: 0.125 | D8: J3 | E8: República Checa | F8: 0 | G8: 1 | H8: México | J8: =IF(OR(Resultados!F8="",Resultados!G8=""),"",IF(AND(F8=Resultados!F8,G8=Resultados!G8),2,IF(((F8>G8)=(Resultados!F8>Resultados!G8))*((F8<G8)=(Resultados!F8<Resultados!G8)),1,0)))
B9: 46198 | C9: 0.125 | D9: J3 | E9: Sudáfrica | F9: 0 | G9: 3 | H9: Corea del Sur | J9: =IF(OR(Resultados!F9="",Resultados!G9=""),"",IF(AND(F9=Resultados!F9,G9=Resultados!G9),2,IF(((F9>G9)=(Resultados!F9>Resultados!G9))*((F9<G9)=(Resultados!F9<Resultados!G9)),1,0)))
B11: Fecha | C11: Hora | D11: Jor. | E11: Casa | F11: Gol | G11: Gol | H11: Fuera
A12: B | B12: 46185 | C12: 0.875 | D12: J1 | E12: Canadá | F12: 1 | G12: 1 | H12: Bosnia y Herzegovina
B13: 46186 | C13: 0.875 | D13: J1 | E13: Catar | F13: 1 | G13: 1 | H13: Suiza
B14: 46191 | C14: 0.875 | D14: J2 | E14: Suiza | F14: 1 | G14: 2 | H14: Bosnia y Herzegovina | J14: =IF(OR(Resultados!F14="",Resultados!G14=""),"",IF(AND(F14=Resultados!F14,G14=Resultados!G14),2,IF(((F14>G14)=(Resultados!F14>Resultados!G14))*((F14<G14)=(Resultados!F14<Resultados!G14)),1,0)))
B15: 46192 | C15: 0 | D15: J2 | E15: Canadá | F15: 2 | G15: 0 | H15: Catar | J15: =IF(OR(Resultados!F15="",Resultados!G15=""),"",IF(AND(F15=Resultados!F15,G15=Resultados!G15),2,IF(((F15>G15)=(Resultados!F15>Resultados!G15))*((F15<G15)=(Resultados!F15<Resultados!G15)),1,0)))
B16: 46197 | C16: 0.875 | D16: J3 | E16: Suiza | F16: 2 | G16: 1 | H16: Canadá | J16: =IF(OR(Resultados!F16="",Resultados!G16=""),"",IF(AND(F16=Resultados!F16,G16=Resultados!G16),2,IF(((F16>G16)=(Resultados!F16>Resultados!G16))*((F16<G16)=(Resultados!F16<Resultados!G16)),1,0)))
B17: 46197 | C17: 0.875 | D17: J3 | E17: Bosnia y Herzegovina | F17: 2 | G17: 0 | H17: Catar | J17: =IF(OR(Resultados!F17="",Resultados!G17=""),"",IF(AND(F17=Resultados!F17,G17=Resultados!G17),2,IF(((F17>G17)=(Resultados!F17>Resultados!G17))*((F17<G17)=(Resultados!F17<Resultados!G17)),1,0)))
B19: Fecha | C19: Hora | D19: Jor. | E19: Casa | F19: Gol | G19: Gol | H19: Fuera
A20: C | B20: 46187 | C20: 0 | D20: J1 | E20: Brasil | F20: 1 | G20: 1 | H20: Marruecos
B21: 46187 | C21: 0.125 | D21: J1 | E21: Haití | F21: 0 | G21: 1 | H21: Escocia | J21: =IF(OR(Resultados!F21="",Resultados!G21=""),"",IF(AND(F21=Resultados!F21,G21=Resultados!G21),2,IF(((F21>G21)=(Resultados!F21>Resultados!G21))*((F21<G21)=(Resultados!F21<Resultados!G21)),1,0))) -> 2
B22: 46193 | C22: 0 | D22: J2 | E22: Escocia | F22: 0 | G22: 1 | H22: Marruecos | J22: =IF(OR(Resultados!F22="",Resultados!G22=""),"",IF(AND(F22=Resultados!F22,G22=Resultados!G22),2,IF(((F22>G22)=(Resultados!F22>Resultados!G22))*((F22<G22)=(Resultados!F22<Resultados!G22)),1,0)))
B23: 46193 | C23: 0.10416667 | D23: J2 | E23: Brasil | F23: 5 | G23: 0 | H23: Haití | J23: =IF(OR(Resultados!F23="",Resultados!G23=""),"",IF(AND(F23=Resultados!F23,G23=Resultados!G23),2,IF(((F23>G23)=(Resultados!F23>Resultados!G23))*((F23<G23)=(Resultados!F23<Resultados!G23)),1,0)))
B24: 46198 | C24: 0 | D24: J3 | E24: Escocia | F24: 0 | G24: 3 | H24: Brasil | J24: =IF(OR(Resultados!F24="",Resultados!G24=""),"",IF(AND(F24=Resultados!F24,G24=Resultados!G24),2,IF(((F24>G24)=(Resultados!F24>Resultados!G24))*((F24<G24)=(Resultados!F24<Resultados!G24)),1,0)))
B25: 46198 | C25: 0 | D25: J3 | E25: Marruecos | F25: 2 | G25: 0 | H25: Haití | J25: =IF(OR(Resultados!F25="",Resultados!G25=""),"",IF(AND(F25=Resultados!F25,G25=Resultados!G25),2,IF(((F25>G25)=(Resultados!F25>Resultados!G25))*((F25<G25)=(Resultados!F25<Resultados!G25)),1,0)))
B27: Fecha | C27: Hora | D27: Jor. | E27: Casa | F27: Gol | G27: Gol | H27: Fuera
A28: D | B28: 46186 | C28: 0.125 | D28: J1 | E28: Estados Unidos | F28: 4 | G28: 1 | H28: Paraguay
B29: 46187 | C29: 0.25 | D29: J1 | E29: Australia | F29: 0 | G29: 2 | H29: Turquía | J29: =IF(OR(Resultados!F29="",Resultados!G29=""),"",IF(AND(F29=Resultados!F29,G29=Resultados!G29),2,IF(((F29>G29)=(Resultados!F29>Resultados!G29))*((F29<G29)=(Resultados!F29<Resultados!G29)),1,0))) -> 0
B30: 46192 | C30: 0.875 | D30: J2 | E30: Estados Unidos | F30: 3 | G30: 0 | H30: Australia | J30: =IF(OR(Resultados!F30="",Resultados!G30=""),"",IF(AND(F30=Resultados!F30,G30=Resultados!G30),2,IF(((F30>G30)=(Resultados!F30>Resultados!G30))*((F30<G30)=(Resultados!F30<Resultados!G30)),1,0)))
B31: 46193 | C31: 0.20833333 | D31: J2 | E31: Turquía | F31: 2 | G31: 0 | H31: Paraguay | J31: =IF(OR(Resultados!F31="",Resultados!G31=""),"",IF(AND(F31=Resultados!F31,G31=Resultados!G31),2,IF(((F31>G31)=(Resultados!F31>Resultados!G31))*((F31<G31)=(Resultados!F31<Resultados!G31)),1,0)))
B32: 46199 | C32: 0.16666667 | D32: J3 | E32: Turquía | F32: 1 | G32: 2 | H32: Estados Unidos | J32: =IF(OR(Resultados!F32="",Resultados!G32=""),"",IF(AND(F32=Resultados!F32,G32=Resultados!G32),2,IF(((F32>G32)=(Resultados!F32>Resultados!G32))*((F32<G32)=(Resultados!F32<Resultados!G32)),1,0)))
B33: 46199 | C33: 0.16666667 | D33: J3 | E33: Paraguay | F33: 2 | G33: 0 | H33: Australia | J33: =IF(OR(Resultados!F33="",Resultados!G33=""),"",IF(AND(F33=Resultados!F33,G33=Resultados!G33),2,IF(((F33>G33)=(Resultados!F33>Resultados!G33))*((F33<G33)=(Resultados!F33<Resultados!G33)),1,0)))
B35: Fecha | C35: Hora | D35: Jor. | E35: Casa | F35: Gol | G35: Gol | H35: Fuera
A36: E | B36: 46187 | C36: 0.79166667 | D36: J1 | E36: Alemania | F36: 4 | G36: 0 | H36: Curazao | J36: =IF(OR(Resultados!F36="",Resultados!G36=""),"",IF(AND(F36=Resultados!F36,G36=Resultados!G36),2,IF(((F36>G36)=(Resultados!F36>Resultados!G36))*((F36<G36)=(Resultados!F36<Resultados!G36)),1,0))) -> 1
B37: 46188 | C37: 0.041666667 | D37: J1 | E37: Costa de Marfil | F37: 1 | G37: 1 | H37: Ecuador | J37: =IF(OR(Resultados!F37="",Resultados!G37=""),"",IF(AND(F37=Resultados!F37,G37=Resultados!G37),2,IF(((F37>G37)=(Resultados!F37>Resultados!G37))*((F37<G37)=(Resultados!F37<Resultados!G37)),1,0))) -> 0
B38: 46193 | C38: 0.91666667 | D38: J2 | E38: Alemania | F38: 2 | G38: 1 | H38: Costa de Marfil | J38: =IF(OR(Resultados!F38="",Resultados!G38=""),"",IF(AND(F38=Resultados!F38,G38=Resultados!G38),2,IF(((F38>G38)=(Resultados!F38>Resultados!G38))*((F38<G38)=(Resultados!F38<Resultados!G38)),1,0)))
B39: 46194 | C39: 0.083333333 | D39: J2 | E39: Ecuador | F39: 3 | G39: 0 | H39: Curazao | J39: =IF(OR(Resultados!F39="",Resultados!G39=""),"",IF(AND(F39=Resultados!F39,G39=Resultados!G39),2,IF(((F39>G39)=(Resultados!F39>Resultados!G39))*((F39<G39)=(Resultados!F39<Resultados!G39)),1,0)))
B40: 46198 | C40: 0.91666667 | D40: J3 | E40: Curazao | F40: 0 | G40: 2 | H40: Costa de Marfil | J40: =IF(OR(Resultados!F40="",Resultados!G40=""),"",IF(AND(F40=Resultados!F40,G40=Resultados!G40),2,IF(((F40>G40)=(Resultados!F40>Resultados!G40))*((F40<G40)=(Resultados!F40<Resultados!G40)),1,0)))
B41: 46198 | C41: 0.91666667 | D41: J3 | E41: Ecuador | F41: 1 | G41: 2 | H41: Alemania | J41: =IF(OR(Resultados!F41="",Resultados!G41=""),"",IF(AND(F41=Resultados!F41,G41=Resultados!G41),2,IF(((F41>G41)=(Resultados!F41>Resultados!G41))*((F41<G41)=(Resultados!F41<Resultados!G41)),1,0)))
B43: Fecha | C43: Hora | D43: Jor. | E43: Casa | F43: Gol | G43: Gol | H43: Fuera
A44: F | B44: 46187 | C44: 0.91666667 | D44: J1 | E44: Países Bajos | F44: 1 | G44: 0 | H44: Japón | J44: =IF(OR(Resultados!F44="",Resultados!G44=""),"",IF(AND(F44=Resultados!F44,G44=Resultados!G44),2,IF(((F44>G44)=(Resultados!F44>Resultados!G44))*((F44<G44)=(Resultados!F44<Resultados!G44)),1,0))) -> 0
B45: 46188 | C45: 0.16666667 | D45: J1 | E45: Suecia | F45: 2 | G45: 0 | H45: Túnez | J45: =IF(OR(Resultados!F45="",Resultados!G45=""),"",IF(AND(F45=Resultados!F45,G45=Resultados!G45),2,IF(((F45>G45)=(Resultados!F45>Resultados!G45))*((F45<G45)=(Resultados!F45<Resultados!G45)),1,0))) -> 1
B46: 46193 | C46: 0.79166667 | D46: J2 | E46: Países Bajos | F46: 2 | G46: 1 | H46: Suecia | J46: =IF(OR(Resultados!F46="",Resultados!G46=""),"",IF(AND(F46=Resultados!F46,G46=Resultados!G46),2,IF(((F46>G46)=(Resultados!F46>Resultados!G46))*((F46<G46)=(Resultados!F46<Resultados!G46)),1,0)))
...

Sheet Bere
A1: XXIII Mundial USA/MEX/CAN 2026
B3: Fecha | C3: Hora | D3: Jor. | E3: Casa | F3: Gol | G3: Gol | H3: Fuera | J3: Puntos | L3: Total
A4: A | B4: 46184 | C4: 0.875 | D4: J1 | E4: México | F4: 2 | G4: 0 | H4: Sudáfrica | L4: =SUM(J:J) -> 5
B5: 46185 | C5: 0.16666667 | D5: J1 | E5: Corea del Sur | F5: 2 | G5: 1 | H5: República Checa
B6: 46191 | C6: 0.75 | D6: J2 | E6: República Checa | F6: 3 | G6: 0 | H6: Sudáfrica | J6: =IF(OR(Resultados!F6="",Resultados!G6=""),"",IF(AND(F6=Resultados!F6,G6=Resultados!G6),2,IF(((F6>G6)=(Resultados!F6>Resultados!G6))*((F6<G6)=(Resultados!F6<Resultados!G6)),1,0)))
B7: 46192 | C7: 0.125 | D7: J2 | E7: México | F7: 1 | G7: 1 | H7: Corea del Sur | J7: =IF(OR(Resultados!F7="",Resultados!G7=""),"",IF(AND(F7=Resultados!F7,G7=Resultados!G7),2,IF(((F7>G7)=(Resultados!F7>Resultados!G7))*((F7<G7)=(Resultados!F7<Resultados!G7)),1,0)))
B8: 46198 | C8: 0.125 | D8: J3 | E8: República Checa | F8: 1 | G8: 2 | H8: México | J8: =IF(OR(Resultados!F8="",Resultados!G8=""),"",IF(AND(F8=Resultados!F8,G8=Resultados!G8),2,IF(((F8>G8)=(Resultados!F8>Resultados!G8))*((F8<G8)=(Resultados!F8<Resultados!G8)),1,0)))
B9: 46198 | C9: 0.125 | D9: J3 | E9: Sudáfrica | F9: 0 | G9: 3 | H9: Corea del Sur | J9: =IF(OR(Resultados!F9="",Resultados!G9=""),"",IF(AND(F9=Resultados!F9,G9=Resultados!G9),2,IF(((F9>G9)=(Resultados!F9>Resultados!G9))*((F9<G9)=(Resultados!F9<Resultados!G9)),1,0)))
B11: Fecha | C11: Hora | D11: Jor. | E11: Casa | F11: Gol | G11: Gol | H11: Fuera
A12: B | B12: 46185 | C12: 0.875 | D12: J1 | E12: Canadá | F12: 1 | G12: 1 | H12: Bosnia y Herzegovina
B13: 46186 | C13: 0.875 | D13: J1 | E13: Catar | F13: 1 | G13: 1 | H13: Suiza
B14: 46191 | C14: 0.875 | D14: J2 | E14: Suiza | F14: 1 | G14: 0 | H14: Bosnia y Herzegovina | J14: =IF(OR(Resultados!F14="",Resultados!G14=""),"",IF(AND(F14=Resultados!F14,G14=Resultados!G14),2,IF(((F14>G14)=(Resultados!F14>Resultados!G14))*((F14<G14)=(Resultados!F14<Resultados!G14)),1,0)))
B15: 46192 | C15: 0 | D15: J2 | E15: Canadá | F15: 2 | G15: 1 | H15: Catar | J15: =IF(OR(Resultados!F15="",Resultados!G15=""),"",IF(AND(F15=Resultados!F15,G15=Resultados!G15),2,IF(((F15>G15)=(Resultados!F15>Resultados!G15))*((F15<G15)=(Resultados!F15<Resultados!G15)),1,0)))
B16: 46197 | C16: 0.875 | D16: J3 | E16: Suiza | F16: 1 | G16: 1 | H16: Canadá | J16: =IF(OR(Resultados!F16="",Resultados!G16=""),"",IF(AND(F16=Resultados!F16,G16=Resultados!G16),2,IF(((F16>G16)=(Resultados!F16>Resultados!G16))*((F16<G16)=(Resultados!F16<Resultados!G16)),1,0)))
B17: 46197 | C17: 0.875 | D17: J3 | E17: Bosnia y Herzegovina | F17: 1 | G17: 0 | H17: Catar | J17: =IF(OR(Resultados!F17="",Resultados!G17=""),"",IF(AND(F17=Resultados!F17,G17=Resultados!G17),2,IF(((F17>G17)=(Resultados!F17>Resultados!G17))*((F17<G17)=(Resultados!F17<Resultados!G17)),1,0)))
B19: Fecha | C19: Hora | D19: Jor. | E19: Casa | F19: Gol | G19: Gol | H19: Fuera
A20: C | B20: 46187 | C20: 0 | D20: J1 | E20: Brasil | F20: 1 | G20: 1 | H20: Marruecos
B21: 46187 | C21: 0.125 | D21: J1 | E21: Haití | F21: 1 | G21: 3 | H21: Escocia | J21: =IF(OR(Resultados!F21="",Resultados!G21=""),"",IF(AND(F21=Resultados!F21,G21=Resultados!G21),2,IF(((F21>G21)=(Resultados!F21>Resultados!G21))*((F21<G21)=(Resultados!F21<Resultados!G21)),1,0))) -> 1
B22: 46193 | C22: 0 | D22: J2 | E22: Escocia | F22: 1 | G22: 2 | H22: Marruecos | J22: =IF(OR(Resultados!F22="",Resultados!G22=""),"",IF(AND(F22=Resultados!F22,G22=Resultados!G22),2,IF(((F22>G22)=(Resultados!F22>Resultados!G22))*((F22<G22)=(Resultados!F22<Resultados!G22)),1,0)))
B23: 46193 | C23: 0.10416667 | D23: J2 | E23: Brasil | F23: 3 | G23: 0 | H23: Haití | J23: =IF(OR(Resultados!F23="",Resultados!G23=""),"",IF(AND(F23=Resultados!F23,G23=Resultados!G23),2,IF(((F23>G23)=(Resultados!F23>Resultados!G23))*((F23<G23)=(Resultados!F23<Resultados!G23)),1,0)))
B24: 46198 | C24: 0 | D24: J3 | E24: Escocia | F24: 1 | G24: 2 | H24: Brasil | J24: =IF(OR(Resultados!F24="",Resultados!G24=""),"",IF(AND(F24=Resultados!F24,G24=Resultados!G24),2,IF(((F24>G24)=(Resultados!F24>Resultados!G24))*((F24<G24)=(Resultados!F24<Resultados!G24)),1,0)))
B25: 46198 | C25: 0 | D25: J3 | E25: Marruecos | F25: 3 | G25: 0 | H25: Haití | J25: =IF(OR(Resultados!F25="",Resultados!G25=""),"",IF(AND(F25=Resultados!F25,G25=Resultados!G25),2,IF(((F25>G25)=(Resultados!F25>Resultados!G25))*((F25<G25)=(Resultados!F25<Resultados!G25)),1,0)))
B27: Fecha | C27: Hora | D27: Jor. | E27: Casa | F27: Gol | G27: Gol | H27: Fuera
A28: D | B28: 46186 | C28: 0.125 | D28: J1 | E28: Estados Unidos | F28: 4 | G28: 1 | H28: Paraguay
B29: 46187 | C29: 0.25 | D29: J1 | E29: Australia | F29: 0 | G29: 2 | H29: Turquía | J29: =IF(OR(Resultados!F29="",Resultados!G29=""),"",IF(AND(F29=Resultados!F29,G29=Resultados!G29),2,IF(((F29>G29)=(Resultados!F29>Resultados!G29))*((F29<G29)=(Resultados!F29<Resultados!G29)),1,0))) -> 0
B30: 46192 | C30: 0.875 | D30: J2 | E30: Estados Unidos | F30: 2 | G30: 0 | H30: Australia | J30: =IF(OR(Resultados!F30="",Resultados!G30=""),"",IF(AND(F30=Resultados!F30,G30=Resultados!G30),2,IF(((F30>G30)=(Resultados!F30>Resultados!G30))*((F30<G30)=(Resultados!F30<Resultados!G30)),1,0)))
B31: 46193 | C31: 0.20833333 | D31: J2 | E31: Turquía | F31: 1 | G31: 1 | H31: Paraguay | J31: =IF(OR(Resultados!F31="",Resultados!G31=""),"",IF(AND(F31=Resultados!F31,G31=Resultados!G31),2,IF(((F31>G31)=(Resultados!F31>Resultados!G31))*((F31<G31)=(Resultados!F31<Resultados!G31)),1,0)))
B32: 46199 | C32: 0.16666667 | D32: J3 | E32: Turquía | H32: Estados Unidos | J32: =IF(OR(Resultados!F32="",Resultados!G32=""),"",IF(AND(F32=Resultados!F32,G32=Resultados!G32),2,IF(((F32>G32)=(Resultados!F32>Resultados!G32))*((F32<G32)=(Resultados!F32<Resultados!G32)),1,0)))
B33: 46199 | C33: 0.16666667 | D33: J3 | E33: Paraguay | H33: Australia | J33: =IF(OR(Resultados!F33="",Resultados!G33=""),"",IF(AND(F33=Resultados!F33,G33=Resultados!G33),2,IF(((F33>G33)=(Resultados!F33>Resultados!G33))*((F33<G33)=(Resultados!F33<Resultados!G33)),1,0)))
B35: Fecha | C35: Hora | D35: Jor. | E35: Casa | F35: Gol | G35: Gol | H35: Fuera
A36: E | B36: 46187 | C36: 0.79166667 | D36: J1 | E36: Alemania | F36: 3 | G36: 0 | H36: Curazao | J36: =IF(OR(Resultados!F36="",Resultados!G36=""),"",IF(AND(F36=Resultados!F36,G36=Resultados!G36),2,IF(((F36>G36)=(Resultados!F36>Resultados!G36))*((F36<G36)=(Resultados!F36<Resultados!G36)),1,0))) -> 1
B37: 46188 | C37: 0.041666667 | D37: J1 | E37: Costa de Marfil | F37: 2 | G37: 2 | H37: Ecuador | J37: =IF(OR(Resultados!F37="",Resultados!G37=""),"",IF(AND(F37=Resultados!F37,G37=Resultados!G37),2,IF(((F37>G37)=(Resultados!F37>Resultados!G37))*((F37<G37)=(Resultados!F37<Resultados!G37)),1,0))) -> 0
B38: 46193 | C38: 0.91666667 | D38: J2 | E38: Alemania | H38: Costa de Marfil | J38: =IF(OR(Resultados!F38="",Resultados!G38=""),"",IF(AND(F38=Resultados!F38,G38=Resultados!G38),2,IF(((F38>G38)=(Resultados!F38>Resultados!G38))*((F38<G38)=(Resultados!F38<Resultados!G38)),1,0)))
B39: 46194 | C39: 0.083333333 | D39: J2 | E39: Ecuador | H39: Curazao | J39: =IF(OR(Resultados!F39="",Resultados!G39=""),"",IF(AND(F39=Resultados!F39,G39=Resultados!G39),2,IF(((F39>G39)=(Resultados!F39>Resultados!G39))*((F39<G39)=(Resultados!F39<Resultados!G39)),1,0)))
B40: 46198 | C40: 0.91666667 | D40: J3 | E40: Curazao | H40: Costa de Marfil | J40: =IF(OR(Resultados!F40="",Resultados!G40=""),"",IF(AND(F40=Resultados!F40,G40=Resultados!G40),2,IF(((F40>G40)=(Resultados!F40>Resultados!G40))*((F40<G40)=(Resultados!F40<Resultados!G40)),1,0)))
B41: 46198 | C41: 0.91666667 | D41: J3 | E41: Ecuador | H41: Alemania | J41: =IF(OR(Resultados!F41="",Resultados!G41=""),"",IF(AND(F41=Resultados!F41,G41=Resultados!G41),2,IF(((F41>G41)=(Resultados!F41>Resultados!G41))*((F41<G41)=(Resultados!F41<Resultados!G41)),1,0)))
B43: Fecha | C43: Hora | D43: Jor. | E43: Casa | F43: Gol | G43: Gol | H43: Fuera
A44: F | B44: 46187 | C44: 0.91666667 | D44: J1 | E44: Países Bajos | F44: 2 | G44: 2 | H44: Japón | J44: =IF(OR(Resultados!F44="",Resultados!G44=""),"",IF(AND(F44=Resultados!F44,G44=Resultados!G44),2,IF(((F44>G44)=(Resultados!F44>Resultados!G44))*((F44<G44)=(Resultados!F44<Resultados!G44)),1,0))) -> 2
B45: 46188 | C45: 0.16666667 | D45: J1 | E45: Suecia | F45: 2 | G45: 1 | H45: Túnez | J45: =IF(OR(Resultados!F45="",Resultados!G45=""),"",IF(AND(F45=Resultados!F45,G45=Resultados!G45),2,IF(((F45>G45)=(Resultados!F45>Resultados!G45))*((F45<G45)=(Resultados!F45<Resultados!G45)),1,0))) -> 1
B46: 46193 | C46: 0.79166667 | D46: J2 | E46: Países Bajos | H46: Suecia | J46: =IF(OR(Resultados!F46="",Resultados!G46=""),"",IF(AND(F46=Resultados!F46,G46=Resultados!G46),2,IF(((F46>G46)=(Resultados!F46>Resultados!G46))*((F46<G46)=(Resultados!F46<Resultados!G46)),1,0)))
...

Sheet Erick
A1: XXIII Mundial USA/MEX/CAN 2026
B3: Fecha | C3: Hora | D3: Jor. | E3: Casa | F3: Gol | G3: Gol | H3: Fuera | J3: Puntos | L3: Total
A4: A | B4: 46184 | C4: 0.875 | D4: J1 | E4: México | F4: 2 | G4: 0 | H4: Sudáfrica | L4: =SUM(J:J) -> 4
B5: 46185 | C5: 0.16666667 | D5: J1 | E5: Corea del Sur | F5: 2 | G5: 1 | H5: República Checa
B6: 46191 | C6: 0.75 | D6: J2 | E6: República Checa | F6: 2 | G6: 0 | H6: Sudáfrica | J6: =IF(OR(Resultados!F6="",Resultados!G6=""),"",IF(AND(F6=Resultados!F6,G6=Resultados!G6),2,IF(((F6>G6)=(Resultados!F6>Resultados!G6))*((F6<G6)=(Resultados!F6<Resultados!G6)),1,0)))
B7: 46192 | C7: 0.125 | D7: J2 | E7: México | F7: 2 | G7: 1 | H7: Corea del Sur | J7: =IF(OR(Resultados!F7="",Resultados!G7=""),"",IF(AND(F7=Resultados!F7,G7=Resultados!G7),2,IF(((F7>G7)=(Resultados!F7>Resultados!G7))*((F7<G7)=(Resultados!F7<Resultados!G7)),1,0)))
B8: 46198 | C8: 0.125 | D8: J3 | E8: República Checa | F8: 0 | G8: 1 | H8: México | J8: =IF(OR(Resultados!F8="",Resultados!G8=""),"",IF(AND(F8=Resultados!F8,G8=Resultados!G8),2,IF(((F8>G8)=(Resultados!F8>Resultados!G8))*((F8<G8)=(Resultados!F8<Resultados!G8)),1,0)))
B9: 46198 | C9: 0.125 | D9: J3 | E9: Sudáfrica | F9: 0 | G9: 2 | H9: Corea del Sur | J9: =IF(OR(Resultados!F9="",Resultados!G9=""),"",IF(AND(F9=Resultados!F9,G9=Resultados!G9),2,IF(((F9>G9)=(Resultados!F9>Resultados!G9))*((F9<G9)=(Resultados!F9<Resultados!G9)),1,0)))
B11: Fecha | C11: Hora | D11: Jor. | E11: Casa | F11: Gol | G11: Gol | H11: Fuera
A12: B | B12: 46185 | C12: 0.875 | D12: J1 | E12: Canadá | F12: 1 | G12: 1 | H12: Bosnia y Herzegovina
B13: 46186 | C13: 0.875 | D13: J1 | E13: Catar | F13: 1 | G13: 1 | H13: Suiza
B14: 46191 | C14: 0.875 | D14: J2 | E14: Suiza | F14: 1 | G14: 1 | H14: Bosnia y Herzegovina | J14: =IF(OR(Resultados!F14="",Resultados!G14=""),"",IF(AND(F14=Resultados!F14,G14=Resultados!G14),2,IF(((F14>G14)=(Resultados!F14>Resultados!G14))*((F14<G14)=(Resultados!F14<Resultados!G14)),1,0)))
B15: 46192 | C15: 0 | D15: J2 | E15: Canadá | F15: 2 | G15: 1 | H15: Catar | J15: =IF(OR(Resultados!F15="",Resultados!G15=""),"",IF(AND(F15=Resultados!F15,G15=Resultados!G15),2,IF(((F15>G15)=(Resultados!F15>Resultados!G15))*((F15<G15)=(Resultados!F15<Resultados!G15)),1,0)))
B16: 46197 | C16: 0.875 | D16: J3 | E16: Suiza | F16: 1 | G16: 1 | H16: Canadá | J16: =IF(OR(Resultados!F16="",Resultados!G16=""),"",IF(AND(F16=Resultados!F16,G16=Resultados!G16),2,IF(((F16>G16)=(Resultados!F16>Resultados!G16))*((F16<G16)=(Resultados!F16<Resultados!G16)),1,0)))
B17: 46197 | C17: 0.875 | D17: J3 | E17: Bosnia y Herzegovina | F17: 1 | G17: 0 | H17: Catar | J17: =IF(OR(Resultados!F17="",Resultados!G17=""),"",IF(AND(F17=Resultados!F17,G17=Resultados!G17),2,IF(((F17>G17)=(Resultados!F17>Resultados!G17))*((F17<G17)=(Resultados!F17<Resultados!G17)),1,0)))
B19: Fecha | C19: Hora | D19: Jor. | E19: Casa | F19: Gol | G19: Gol | H19: Fuera
A20: C | B20: 46187 | C20: 0 | D20: J1 | E20: Brasil | F20: 1 | G20: 1 | H20: Marruecos
B21: 46187 | C21: 0.125 | D21: J1 | E21: Haití | F21: 0 | G21: 1 | H21: Escocia | J21: =IF(OR(Resultados!F21="",Resultados!G21=""),"",IF(AND(F21=Resultados!F21,G21=Resultados!G21),2,IF(((F21>G21)=(Resultados!F21>Resultados!G21))*((F21<G21)=(Resultados!F21<Resultados!G21)),1,0))) -> 2
B22: 46193 | C22: 0 | D22: J2 | E22: Escocia | F22: 0 | G22: 3 | H22: Marruecos | J22: =IF(OR(Resultados!F22="",Resultados!G22=""),"",IF(AND(F22=Resultados!F22,G22=Resultados!G22),2,IF(((F22>G22)=(Resultados!F22>Resultados!G22))*((F22<G22)=(Resultados!F22<Resultados!G22)),1,0)))
B23: 46193 | C23: 0.10416667 | D23: J2 | E23: Brasil | F23: 5 | G23: 0 | H23: Haití | J23: =IF(OR(Resultados!F23="",Resultados!G23=""),"",IF(AND(F23=Resultados!F23,G23=Resultados!G23),2,IF(((F23>G23)=(Resultados!F23>Resultados!G23))*((F23<G23)=(Resultados!F23<Resultados!G23)),1,0)))
B24: 46198 | C24: 0 | D24: J3 | E24: Escocia | F24: 0 | G24: 3 | H24: Brasil | J24: =IF(OR(Resultados!F24="",Resultados!G24=""),"",IF(AND(F24=Resultados!F24,G24=Resultados!G24),2,IF(((F24>G24)=(Resultados!F24>Resultados!G24))*((F24<G24)=(Resultados!F24<Resultados!G24)),1,0)))
B25: 46198 | C25: 0 | D25: J3 | E25: Marruecos | F25: 4 | G25: 0 | H25: Haití | J25: =IF(OR(Resultados!F25="",Resultados!G25=""),"",IF(AND(F25=Resultados!F25,G25=Resultados!G25),2,IF(((F25>G25)=(Resultados!F25>Resultados!G25))*((F25<G25)=(Resultados!F25<Resultados!G25)),1,0)))
B27: Fecha | C27: Hora | D27: Jor. | E27: Casa | F27: Gol | G27: Gol | H27: Fuera
A28: D | B28: 46186 | C28: 0.125 | D28: J1 | E28: Estados Unidos | F28: 4 | G28: 1 | H28: Paraguay
B29: 46187 | C29: 0.25 | D29: J1 | E29: Australia | F29: 0 | G29: 2 | H29: Turquía | J29: =IF(OR(Resultados!F29="",Resultados!G29=""),"",IF(AND(F29=Resultados!F29,G29=Resultados!G29),2,IF(((F29>G29)=(Resultados!F29>Resultados!G29))*((F29<G29)=(Resultados!F29<Resultados!G29)),1,0))) -> 0
B30: 46192 | C30: 0.875 | D30: J2 | E30: Estados Unidos | F30: 3 | G30: 0 | H30: Australia | J30: =IF(OR(Resultados!F30="",Resultados!G30=""),"",IF(AND(F30=Resultados!F30,G30=Resultados!G30),2,IF(((F30>G30)=(Resultados!F30>Resultados!G30))*((F30<G30)=(Resultados!F30<Resultados!G30)),1,0)))
B31: 46193 | C31: 0.20833333 | D31: J2 | E31: Turquía | F31: 1 | G31: 1 | H31: Paraguay | J31: =IF(OR(Resultados!F31="",Resultados!G31=""),"",IF(AND(F31=Resultados!F31,G31=Resultados!G31),2,IF(((F31>G31)=(Resultados!F31>Resultados!G31))*((F31<G31)=(Resultados!F31<Resultados!G31)),1,0)))
B32: 46199 | C32: 0.16666667 | D32: J3 | E32: Turquía | F32: 0 | G32: 2 | H32: Estados Unidos | J32: =IF(OR(Resultados!F32="",Resultados!G32=""),"",IF(AND(F32=Resultados!F32,G32=Resultados!G32),2,IF(((F32>G32)=(Resultados!F32>Resultados!G32))*((F32<G32)=(Resultados!F32<Resultados!G32)),1,0)))
B33: 46199 | C33: 0.16666667 | D33: J3 | E33: Paraguay | F33: 1 | G33: 0 | H33: Australia | J33: =IF(OR(Resultados!F33="",Resultados!G33=""),"",IF(AND(F33=Resultados!F33,G33=Resultados!G33),2,IF(((F33>G33)=(Resultados!F33>Resultados!G33))*((F33<G33)=(Resultados!F33<Resultados!G33)),1,0)))
B35: Fecha | C35: Hora | D35: Jor. | E35: Casa | F35: Gol | G35: Gol | H35: Fuera
A36: E | B36: 46187 | C36: 0.79166667 | D36: J1 | E36: Alemania | F36: 5 | G36: 0 | H36: Curazao | J36: =IF(OR(Resultados!F36="",Resultados!G36=""),"",IF(AND(F36=Resultados!F36,G36=Resultados!G36),2,IF(((F36>G36)=(Resultados!F36>Resultados!G36))*((F36<G36)=(Resultados!F36<Resultados!G36)),1,0))) -> 1
B37: 46188 | C37: 0.041666667 | D37: J1 | E37: Costa de Marfil | F37: 1 | G37: 1 | H37: Ecuador | J37: =IF(OR(Resultados!F37="",Resultados!G37=""),"",IF(AND(F37=Resultados!F37,G37=Resultados!G37),2,IF(((F37>G37)=(Resultados!F37>Resultados!G37))*((F37<G37)=(Resultados!F37<Resultados!G37)),1,0))) -> 0
B38: 46193 | C38: 0.91666667 | D38: J2 | E38: Alemania | F38: 2 | G38: 1 | H38: Costa de Marfil | J38: =IF(OR(Resultados!F38="",Resultados!G38=""),"",IF(AND(F38=Resultados!F38,G38=Resultados!G38),2,IF(((F38>G38)=(Resultados!F38>Resultados!G38))*((F38<G38)=(Resultados!F38<Resultados!G38)),1,0)))
B39: 46194 | C39: 0.083333333 | D39: J2 | E39: Ecuador | F39: 3 | G39: 0 | H39: Curazao | J39: =IF(OR(Resultados!F39="",Resultados!G39=""),"",IF(AND(F39=Resultados!F39,G39=Resultados!G39),2,IF(((F39>G39)=(Resultados!F39>Resultados!G39))*((F39<G39)=(Resultados!F39<Resultados!G39)),1,0)))
B40: 46198 | C40: 0.91666667 | D40: J3 | E40: Curazao | F40: 0 | G40: 2 | H40: Costa de Marfil | J40: =IF(OR(Resultados!F40="",Resultados!G40=""),"",IF(AND(F40=Resultados!F40,G40=Resultados!G40),2,IF(((F40>G40)=(Resultados!F40>Resultados!G40))*((F40<G40)=(Resultados!F40<Resultados!G40)),1,0)))
B41: 46198 | C41: 0.91666667 | D41: J3 | E41: Ecuador | F41: 1 | G41: 3 | H41: Alemania | J41: =IF(OR(Resultados!F41="",Resultados!G41=""),"",IF(AND(F41=Resultados!F41,G41=Resultados!G41),2,IF(((F41>G41)=(Resultados!F41>Resultados!G41))*((F41<G41)=(Resultados!F41<Resultados!G41)),1,0)))
B43: Fecha | C43: Hora | D43: Jor. | E43: Casa | F43: Gol | G43: Gol | H43: Fuera
A44: F | B44: 46187 | C44: 0.91666667 | D44: J1 | E44: Países Bajos | F44: 1 | G44: 1 | H44: Japón | J44: =IF(OR(Resultados!F44="",Resultados!G44=""),"",IF(AND(F44=Resultados!F44,G44=Resultados!G44),2,IF(((F44>G44)=(Resultados!F44>Resultados!G44))*((F44<G44)=(Resultados!F44<Resultados!G44)),1,0))) -> 1
B45: 46188 | C45: 0.16666667 | D45: J1 | E45: Suecia | F45: 2 | G45: 2 | H45: Túnez | J45: =IF(OR(Resultados!F45="",Resultados!G45=""),"",IF(AND(F45=Resultados!F45,G45=Resultados!G45),2,IF(((F45>G45)=(Resultados!F45>Resultados!G45))*((F45<G45)=(Resultados!F45<Resultados!G45)),1,0))) -> 0
B46: 46193 | C46: 0.79166667 | D46: J2 | E46: Países Bajos | F46: 2 | G46: 2 | H46: Suecia | J46: =IF(OR(Resultados!F46="",Resultados!G46=""),"",IF(AND(F46=Resultados!F46,G46=Resultados!G46),2,IF(((F46>G46)=(Resultados!F46>Resultados!G46))*((F46<G46)=(Resultados!F46<Resultados!G46)),1,0)))
...

Sheet Erik
A1: XXIII Mundial USA/MEX/CAN 2026
B3: Fecha | C3: Hora | D3: Jor. | E3: Casa | F3: Gol | G3: Gol | H3: Fuera | J3: Puntos | L3: Total
A4: A | B4: 46184 | C4: 0.875 | D4: J1 | E4: México | F4: 2 | G4: 0 | H4: Sudáfrica | L4: =SUM(J:J) -> 4
B5: 46185 | C5: 0.16666667 | D5: J1 | E5: Corea del Sur | F5: 2 | G5: 1 | H5: República Checa
B6: 46191 | C6: 0.75 | D6: J2 | E6: República Checa | F6: 1 | G6: 1 | H6: Sudáfrica | J6: =IF(OR(Resultados!F6="",Resultados!G6=""),"",IF(AND(F6=Resultados!F6,G6=Resultados!G6),2,IF(((F6>G6)=(Resultados!F6>Resultados!G6))*((F6<G6)=(Resultados!F6<Resultados!G6)),1,0)))
B7: 46192 | C7: 0.125 | D7: J2 | E7: México | F7: 2 | G7: 1 | H7: Corea del Sur | J7: =IF(OR(Resultados!F7="",Resultados!G7=""),"",IF(AND(F7=Resultados!F7,G7=Resultados!G7),2,IF(((F7>G7)=(Resultados!F7>Resultados!G7))*((F7<G7)=(Resultados!F7<Resultados!G7)),1,0)))
B8: 46198 | C8: 0.125 | D8: J3 | E8: República Checa | F8: 1 | G8: 1 | H8: México | J8: =IF(OR(Resultados!F8="",Resultados!G8=""),"",IF(AND(F8=Resultados!F8,G8=Resultados!G8),2,IF(((F8>G8)=(Resultados!F8>Resultados!G8))*((F8<G8)=(Resultados!F8<Resultados!G8)),1,0)))
B9: 46198 | C9: 0.125 | D9: J3 | E9: Sudáfrica | F9: 1 | G9: 2 | H9: Corea del Sur | J9: =IF(OR(Resultados!F9="",Resultados!G9=""),"",IF(AND(F9=Resultados!F9,G9=Resultados!G9),2,IF(((F9>G9)=(Resultados!F9>Resultados!G9))*((F9<G9)=(Resultados!F9<Resultados!G9)),1,0)))
B11: Fecha | C11: Hora | D11: Jor. | E11: Casa | F11: Gol | G11: Gol | H11: Fuera
A12: B | B12: 46185 | C12: 0.875 | D12: J1 | E12: Canadá | F12: 1 | G12: 1 | H12: Bosnia y Herzegovina
B13: 46186 | C13: 0.875 | D13: J1 | E13: Catar | F13: 1 | G13: 1 | H13: Suiza
B14: 46191 | C14: 0.875 | D14: J2 | E14: Suiza | F14: 2 | G14: 0 | H14: Bosnia y Herzegovina | J14: =IF(OR(Resultados!F14="",Resultados!G14=""),"",IF(AND(F14=Resultados!F14,G14=Resultados!G14),2,IF(((F14>G14)=(Resultados!F14>Resultados!G14))*((F14<G14)=(Resultados!F14<Resultados!G14)),1,0)))
B15: 46192 | C15: 0 | D15: J2 | E15: Canadá | F15: 1 | G15: 0 | H15: Catar | J15: =IF(OR(Resultados!F15="",Resultados!G15=""),"",IF(AND(F15=Resultados!F15,G15=Resultados!G15),2,IF(((F15>G15)=(Resultados!F15>Resultados!G15))*((F15<G15)=(Resultados!F15<Resultados!G15)),1,0)))
B16: 46197 | C16: 0.875 | D16: J3 | E16: Suiza | F16: 2 | G16: 1 | H16: Canadá | J16: =IF(OR(Resultados!F16="",Resultados!G16=""),"",IF(AND(F16=Resultados!F16,G16=Resultados!G16),2,IF(((F16>G16)=(Resultados!F16>Resultados!G16))*((F16<G16)=(Resultados!F16<Resultados!G16)),1,0)))
B17: 46197 | C17: 0.875 | D17: J3 | E17: Bosnia y Herzegovina | F17: 0 | G17: 0 | H17: Catar | J17: =IF(OR(Resultados!F17="",Resultados!G17=""),"",IF(AND(F17=Resultados!F17,G17=Resultados!G17),2,IF(((F17>G17)=(Resultados!F17>Resultados!G17))*((F17<G17)=(Resultados!F17<Resultados!G17)),1,0)))
B19: Fecha | C19: Hora | D19: Jor. | E19: Casa | F19: Gol | G19: Gol | H19: Fuera
A20: C | B20: 46187 | C20: 0 | D20: J1 | E20: Brasil | F20: 1 | G20: 1 | H20: Marruecos
